Workbook

Sheet Input Nilai
B2: PENILAIAN KETANGGUHAN DESA/KELURAHAN
B4: FORM INPUT PENILAIAN
B5: Tanggal | C5: : | D5: 46217
B6: Nama Desa/Kelurahan | C6: : | D6: Desa Medari
B7: Kecamatan | C7: : | D7: Ngadirejo
B8: Kabupaten/Kota | C8: : | D8: Temanggung
B9: Provinsi | C9: : | D9: Jawa Tengah
B10: JENIS BENCANA | C10: : | D10: Cuaca Ekstrem (Angin Kencang)
A12: KOMPONEN | C12: INDIKATOR | E12: NO PERTANYAAN | F12: RESPON (YA=1, TIDAK=0) | G12: DOKUMEN VERIFIKASI | H12: CATATAN DISKUSI
A13: 1 | B13: LAYANAN DASAR | C13: 1 | D13: Penyelenggaraan Layanan Pendidikan | E13: 1 | F13: 1
E14: 2 | F14: 1
E15: 3 | F15: 1
E16: 4 | F16: 1
C17: 2 | D17: Penyelenggaraan Layanan Kesehatan | E17: 5 | F17: 1
E18: 6 | F18: 1
E19: 7 | F19: 1
E20: 8 | F20: 1
C21: 3 | D21: Sarana dan Prasarana Transportasi | E21: 9 | F21: 1
E22: 10 | F22: 1
E23: 11 | F23: 0
E24: 12 | F24: 0
C25: 4 | D25: Penyediaan Air Bersih | E25: 13 | F25: 1
E26: 14 | F26: 1
E27: 15 | F27: 1
E28: 16 | F28: 1
C29: 5 | D29: Program dan Kegiatan Pangan & Gizi | E29: 17 | F29: 1
E30: 18 | F30: 1
E31: 19 | F31: 1
E32: 20 | F32: 1
C33: 6 | D33: Pemberdayaan UMKM dan Peningkatan Ekonomi Melalui BUMDES | E33: 21 | F33: 1
E34: 22 | F34: 1
E35: 23 | F35: 1
E36: 24 | F36: 1
C37: 7 | D37: Sarana dan Prasarana Komunikasi/Informasi | E37: 25 | F37: 1
E38: 26 | F38: 1
E39: 27 | F39: 1
E40: 28 | F40: 1
C41: 8 | D41: Pelayanan Administrasi dan Kependudukan | E41: 29 | F41: 1
E42: 30 | F42: 1
E43: 31 | F43: 1
...

Sheet Analisa
A1: KOMPONEN | D1: INDIKATOR | E1: ='Input Nilai'!E12 -> NO PERTANYAAN | F1: ='Input Nilai'!F12 -> RESPON (YA=1, TIDAK=0) | G1: NILAI RESPON | H1: TOTAL | I1: ET | J1: MN | K1: IP | L1: YY | M1: HN | N1: WW | O1: IND | P1: ANG | Q1: ROG | R1: PJS | S1: GGH | T1: GDR | U1: HDI | V1: FRZ | W1: VUR | X1: MUT | Y1: NRL | AA1: Nilai Kepentingan | AB1: Bobot % | AC1: INDEKS INDIKATOR | AD1: LEVEL INDIKATOR | AE1: NILAI KEPENTINGAN | AF1: NILAI INDIKATOR | AG1: INDEKS KOMPONEN | AI1: INDEKS KETANGGUHAN | AJ1: Rekomendasi Aksi
A2: 1 | B2: ='Input Nilai'!B13 -> LAYANAN DASAR | C2: ='Input Nilai'!C13 -> 1 | D2: ='Input Nilai'!D13 -> Penyelenggaraan Layanan Pendidikan | E2: ='Input Nilai'!E13 -> 1 | F2: 1 | G2: =IF(F2=1,"2",IF(F2=0,"1")) -> 2 | H2: =((G2+G3+G4+G5)*5/5) -> 5 | I2: 4 | J2: 3 | K2: 4 | L2: 4 | M2: 4 | N2: 4 | O2: 4 | P2: 4 | Q2: 4 | R2: 4 | S2: 4 | T2: 4 | U2: 3 | V2: 4 | W2: 4 | X2: 4 | Y2: 4 | AA2: =SUM(I2:Y4)/17 -> 3.8823529 | AB2: =1/14 -> 0.071428571 | AC2: =IF(H2<1,"0",H2) -> 5 | AD2: =IF(AC2="",0,AC2) -> 5 | AE2: =AB2/5 -> 0.014285714 | AF2: =AD2*AE2 -> 0.071428571 | AG2: =SUM(AF2:AF57) -> 0.87142857 | AH2: 20 | AI2: =(AG2*AH2)+(AG58*AH58)+(AG78*AH78)+(AG90*AH90)+(AG114*AH114) -> 57.161905 | AJ2: =IF(AF2=0,"-", IF(H2=1,'Rekomendasi Aksi'!E2, IF(H2=2,'Rekomendasi Aksi'!E2, IF(H2=3,'Rekomendasi Aksi'!E3, IF(H2=4,'Rekomendasi Aksi'!E4, IF(H2=5,'Rekomendasi Aksi'!E5)))))) -> Melakukan kerjasama dengan dinas/lembaga/organisasi untuk indentifikasi kebutuhan, perencanaan dan pelaksanaan pengembangan/peningkatan penyelenggaraan layanan pendidikan formal/non formal di Desa/Kelurahan.
E3: ='Input Nilai'!E14 -> 2 | F3: ='Input Nilai'!F14 -> 1 | G3: =IF(F3<1,"0",IF(F3=0,"0",IF(F3=1,"1"))) -> 1
E4: ='Input Nilai'!E15 -> 3 | F4: ='Input Nilai'!F15 -> 1 | G4: =IF(F4<1,"0",IF(F4=0,"0",IF(F4=1,"1"))) -> 1
E5: ='Input Nilai'!E16 -> 4 | F5: ='Input Nilai'!F16 -> 1 | G5: =IF(F5<1,"0",IF(F5=0,"0",IF(F5=1,"1"))) -> 1
C6: ='Input Nilai'!C17 -> 2 | D6: ='Input Nilai'!D17 -> Penyelenggaraan Layanan Kesehatan | E6: ='Input Nilai'!E17 -> 5 | F6: ='Input Nilai'!F17 -> 1 | G6: =IF(F6=1,"2",IF(F6=0,"1")) -> 2 | H6: =((G6+G7+G8+G9)*5/5) -> 5 | I6: 4 | J6: 4 | K6: 4 | L6: 3 | M6: 3 | N6: 4 | O6: 4 | P6: 4 | Q6: 4 | R6: 4 | S6: 4 | T6: 4 | U6: 4 | V6: 3 | W6: 3 | X6: 4 | Y6: 4 | AA6: =SUM(I6:Y8)/17 -> 3.7647059 | AB6: =1/14 -> 0.071428571 | AC6: =IF(H6<1,"0",H6) -> 5 | AD6: =IF(AC6="",0,AC6) -> 5 | AE6: =AB6/5 -> 0.014285714 | AF6: =AD6*AE6 -> 0.071428571 | AJ6: =IF(AF6=0,"-", IF(H6=1,'Rekomendasi Aksi'!E6, IF(H6=2,'Rekomendasi Aksi'!E6, IF(H6=3,'Rekomendasi Aksi'!E7, IF(H6=4,'Rekomendasi Aksi'!E8, IF(H6=5,'Rekomendasi Aksi'!E9)))))) -> Melakukan kerjasama dengan dinas/lembaga/organisasi untuk indentifikasi kebutuhan, perencanaan dan pelaksanaan pengembangan/peningkatan penyelenggaraan layanan kesehatan formal/non formal di Desa/Kelurahan.
E7: ='Input Nilai'!E18 -> 6 | F7: ='Input Nilai'!F18 -> 1 | G7: =IF(F7<1,"0",IF(F7=0,"0",IF(F7=1,"1"))) -> 1
E8: ='Input Nilai'!E19 -> 7 | F8: ='Input Nilai'!F19 -> 1 | G8: =IF(F8<1,"0",IF(F8=0,"0",IF(F8=1,"1"))) -> 1
E9: ='Input Nilai'!E20 -> 8 | F9: ='Input Nilai'!F20 -> 1 | G9: =IF(F9<1,"0",IF(F9=0,"0",IF(F9=1,"1"))) -> 1
C10: ='Input Nilai'!C21 -> 3 | D10: ='Input Nilai'!D21 -> Sarana dan Prasarana Transportasi | E10: ='Input Nilai'!E21 -> 9 | F10: ='Input Nilai'!F21 -> 1 | G10: =IF(F10=1,"2",IF(F10=0,"1")) -> 2 | H10: =((G10+G11+G12+G13)*5/5) -> 3 | I10: 3 | J10: 3 | K10: 3 | L10: 1 | M10: 3 | N10: 3 | O10: 3 | P10: 3 | Q10: 2 | R10: 2 | S10: 3 | T10: 3 | U10: 3 | V10: 1 | W10: 2 | X10: 3 | Y10: 3 | AA10: =SUM(I10:Y12)/17 -> 2.5882353 | AB10: =1/14 -> 0.071428571 | AC10: =IF(H10<1,"0",H10) -> 3 | AD10: =IF(AC10="",0,AC10) -> 3 | AE10: =AB10/5 -> 0.014285714 | AF10: =AD10*AE10 -> 0.042857143 | AJ10: =IF(AF10=0,"-", IF(H10=1,'Rekomendasi Aksi'!E10, IF(H10=2,'Rekomendasi Aksi'!E10, IF(H10=3,'Rekomendasi Aksi'!E11, IF(H10=4,'Rekomendasi Aksi'!E12, IF(H10=5,'Rekomendasi Aksi'!E13)))))) -> Melakukan evaluasi, perencanaan dan pelaksanaan layanan sarana/prasarana transportasi
E11: ='Input Nilai'!E22 -> 10 | F11: ='Input Nilai'!F22 -> 1 | G11: =IF(F11<1,"0",IF(F11=0,"0",IF(F11=1,"1"))) -> 1
E12: ='Input Nilai'!E23 -> 11 | F12: ='Input Nilai'!F23 -> 0 | G12: =IF(F12<1,"0",IF(F12=0,"0",IF(F12=1,"1"))) -> 0
E13: ='Input Nilai'!E24 -> 12 | F13: ='Input Nilai'!F24 -> 0 | G13: =IF(F13<1,"0",IF(F13=0,"0",IF(F13=1,"1"))) -> 0
C14: ='Input Nilai'!C25 -> 4 | D14: ='Input Nilai'!D25 -> Penyediaan Air Bersih | E14: ='Input Nilai'!E25 -> 13 | F14: ='Input Nilai'!F25 -> 1 | G14: =IF(F14=1,"2",IF(F14=0,"1")) -> 2 | H14: =((G14+G15+G16+G17)*5/5) -> 5 | I14: 3 | J14: 4 | K14: 4 | L14: 4 | M14: 2 | N14: 3 | O14: 3 | P14: 4 | Q14: 4 | R14: 4 | S14: 4 | T14: 4 | U14: 4 | V14: 3 | W14: 4 | X14: 4 | Y14: 4 | AA14: =SUM(I14:Y16)/17 -> 3.6470588 | AB14: =1/14 -> 0.071428571 | AC14: =IF(H14<1,"0",H14) -> 5 | AD14: =IF(AC14="",0,AC14) -> 5 | AE14: =AB14/5 -> 0.014285714 | AF14: =AD14*AE14 -> 0.071428571 | AJ14: =IF(AF14=0,"-", IF(H14=1,'Rekomendasi Aksi'!E14, IF(H14=2,'Rekomendasi Aksi'!E14, IF(H14=3,'Rekomendasi Aksi'!E15, IF(H14=4,'Rekomendasi Aksi'!E16, IF(H14=5,'Rekomendasi Aksi'!E17)))))) -> Mengusulkan kerjasama dengan dinas/lembaga/organisasi untuk identifikasi kebutuhan, perencanaan dan pelaksanaan penyelenggaraan program layanan air bersih
E15: ='Input Nilai'!E26 -> 14 | F15: ='Input Nilai'!F26 -> 1 | G15: =IF(F15<1,"0",IF(F15=0,"0",IF(F15=1,"1"))) -> 1
E16: ='Input Nilai'!E27 -> 15 | F16: ='Input Nilai'!F27 -> 1 | G16: =IF(F16<1,"0",IF(F16=0,"0",IF(F16=1,"1"))) -> 1
E17: ='Input Nilai'!E28 -> 16 | F17: ='Input Nilai'!F28 -> 1 | G17: =IF(F17<1,"0",IF(F17=0,"0",IF(F17=1,"1"))) -> 1
C18: ='Input Nilai'!C29 -> 5 | D18: ='Input Nilai'!D29 -> Program dan Kegiatan Pangan & Gizi | E18: ='Input Nilai'!E29 -> 17 | F18: ='Input Nilai'!F29 -> 1 | G18: =IF(F18=1,"2",IF(F18=0,"1")) -> 2 | H18: =((G18+G19+G20+G21)*5/5) -> 5 | I18: 2 | J18: 3 | K18: 2 | L18: 3 | M18: 2 | N18: 3 | O18: 3 | P18: 3 | Q18: 3 | R18: 3 | S18: 4 | T18: 4 | U18: 2 | V18: 2 | W18: 3 | X18: 3 | Y18: 3 | AA18: =SUM(I18:Y20)/17 -> 2.8235294 | AB18: =1/14 -> 0.071428571 | AC18: =IF(H18<1,"0",H18) -> 5 | AD18: =IF(AC18="",0,AC18) -> 5 | AE18: =AB18/5 -> 0.014285714 | AF18: =AD18*AE18 -> 0.071428571 | AJ18: =IF(AF18=0,"-", IF(H18=1,'Rekomendasi Aksi'!E18, IF(H18=2,'Rekomendasi Aksi'!E18, IF(H18=3,'Rekomendasi Aksi'!E19, IF(H18=4,'Rekomendasi Aksi'!E20, IF(H18=5,'Rekomendasi Aksi'!E21)))))) -> Melakukan kerjasama dengan berbagai pihak baik OPD terkait, akademisi, praktisi pangan dan gizi serta lembaga lainnya..
E19: ='Input Nilai'!E30 -> 18 | F19: ='Input Nilai'!F30 -> 1 | G19: =IF(F19<1,"0",IF(F19=0,"0",IF(F19=1,"1"))) -> 1
E20: ='Input Nilai'!E31 -> 19 | F20: ='Input Nilai'!F31 -> 1 | G20: =IF(F20<1,"0",IF(F20=0,"0",IF(F20=1,"1"))) -> 1
E21: ='Input Nilai'!E32 -> 20 | F21: ='Input Nilai'!F32 -> 1 | G21: =IF(F21<1,"0",IF(F21=0,"0",IF(F21=1,"1"))) -> 1
C22: ='Input Nilai'!C33 -> 6 | D22: ='Input Nilai'!D33 -> Pemberdayaan UMKM dan Peningkatan Ekonomi Melalui BUMDES | E22: ='Input Nilai'!E33 -> 21 | F22: ='Input Nilai'!F33 -> 1 | G22: =IF(F22=1,"2",IF(F22=0,"1")) -> 2 | H22: =((G22+G23+G24+G25)*5/5) -> 5 | I22: 2 | J22: 3 | K22: 2 | L22: 2 | M22: 3 | N22: 3 | O22: 2 | P22: 3 | Q22: 2 | R22: 3 | S22: 3 | T22: 3 | U22: 2 | V22: 3 | W22: 3 | X22: 3 | Y22: 3 | AA22: =SUM(I22:Y24)/17 -> 2.6470588 | AB22: =1/14 -> 0.071428571 | AC22: =IF(H22<1,"0",H22) -> 5 | AD22: =IF(AC22="",0,AC22) -> 5 | AE22: =AB22/5 -> 0.014285714 | AF22: =AD22*AE22 -> 0.071428571 | AJ22: =IF(AF22=0,"-", IF(H22=1,'Rekomendasi Aksi'!E22, IF(H22=2,'Rekomendasi Aksi'!E22, IF(H22=3,'Rekomendasi Aksi'!E23, IF(H22=4,'Rekomendasi Aksi'!E24, IF(H22=5,'Rekomendasi Aksi'!E25)))))) -> Melakukan kerjasama dengan berbagai pihak baik OPD terkait, Akademisi, dunia usaha maupun Asosiasi layanan pengembangan ekonomi dan bisnis lainnya.
E23: ='Input Nilai'!E34 -> 22 | F23: ='Input Nilai'!F34 -> 1 | G23: =IF(F23<1,"0",IF(F23=0,"0",IF(F23=1,"1"))) -> 1
E24: ='Input Nilai'!E35 -> 23 | F24: ='Input Nilai'!F35 -> 1 | G24: =IF(F24<1,"0",IF(F24=0,"0",IF(F24=1,"1"))) -> 1
E25: ='Input Nilai'!E36 -> 24 | F25: ='Input Nilai'!F36 -> 1 | G25: =IF(F25<1,"0",IF(F25=0,"0",IF(F25=1,"1"))) -> 1
C26: ='Input Nilai'!C37 -> 7 | D26: ='Input Nilai'!D37 -> Sarana dan Prasarana Komunikasi/Informasi | E26: ='Input Nilai'!E37 -> 25 | F26: ='Input Nilai'!F37 -> 1 | G26: =IF(F26=1,"2",IF(F26=0,"1")) -> 2 | H26: =((G26+G27+G28+G29)*5/5) -> 5 | I26: 4 | J26: 3 | K26: 2 | L26: 2 | M26: 2 | N26: 3 | O26: 3 | P26: 3 | Q26: 3 | R26: 3 | S26: 3 | T26: 3 | U26: 3 | V26: 3 | W26: 3 | X26: 3 | Y26: 3 | AA26: =SUM(I26:Y28)/17 -> 2.8823529 | AB26: =1/14 -> 0.071428571 | AC26: =IF(H26<1,"0",H26) -> 5 | AD26: =IF(AC26="",0,AC26) -> 5 | AE26: =AB26/5 -> 0.014285714 | AF26: =AD26*AE26 -> 0.071428571 | AJ26: =IF(AF26=0,"-", IF(H26=1,'Rekomendasi Aksi'!E26, IF(H26=2,'Rekomendasi Aksi'!E26, IF(H26=3,'Rekomendasi Aksi'!E27, IF(H26=4,'Rekomendasi Aksi'!E28, IF(H26=5,'Rekomendasi Aksi'!E29)))))) -> Melakukan kerjasama dengan dinas/lembaga/organisasi untuk indentifikasi kebutuhan, perencanaan dan pelaksanaan pengembangan/peningkatan penyelenggaraan sarana dan prasarana komunikasi/informasi di Desa/Kelurahan.
E27: ='Input Nilai'!E38 -> 26 | F27: ='Input Nilai'!F38 -> 1 | G27: =IF(F27<1,"0",IF(F27=0,"0",IF(F27=1,"1"))) -> 1
E28: ='Input Nilai'!E39 -> 27 | F28: ='Input Nilai'!F39 -> 1 | G28: =IF(F28<1,"0",IF(F28=0,"0",IF(F28=1,"1"))) -> 1
E29: ='Input Nilai'!E40 -> 28 | F29: ='Input Nilai'!F40 -> 1 | G29: =IF(F29<1,"0",IF(F29=0,"0",IF(F29=1,"1"))) -> 1
C30: ='Input Nilai'!C41 -> 8 | D30: ='Input Nilai'!D41 -> Pelayanan Administrasi dan Kependudukan | E30: ='Input Nilai'!E41 -> 29 | F30: ='Input Nilai'!F41 -> 1 | G30: =IF(F30=1,"2",IF(F30=0,"1")) -> 2 | H30: =((G30+G31+G32+G33)*5/5) -> 5 | I30: 2 | J30: 2 | K30: 2 | L30: 1 | M30: 2 | N30: 2 | O30: 4 | P30: 3 | Q30: 4 | R30: 3 | S30: 2 | T30: 3 | U30: 3 | V30: 1 | W30: 2 | X30: 2 | Y30: 4 | AA30: =SUM(I30:Y32)/17 -> 2.4705882 | AB30: =1/14 -> 0.071428571 | AC30: =IF(H30<1,"0",H30) -> 5 | AD30: =IF(AC30="",0,AC30) -> 5 | AE30: =AB30/5 -> 0.014285714 | AF30: =AD30*AE30 -> 0.071428571 | AJ30: =IF(AF30=0,"-", IF(H30=1,'Rekomendasi Aksi'!E30, IF(H30=2,'Rekomendasi Aksi'!E30, IF(H30=3,'Rekomendasi Aksi'!E31, IF(H30=4,'Rekomendasi Aksi'!E32, IF(H30=5,'Rekomendasi Aksi'!E33)))))) -> Melakukan kerjasama dengan dinas/lembaga/organisasi untuk indentifikasi kebutuhan, perencanaan dan pelaksanaan pengembangan/peningkatan penyelenggaraan pelayanan administrasi dan kependudukan di Desa/Kelurahan.
E31: ='Input Nilai'!E42 -> 30 | F31: ='Input Nilai'!F42 -> 1 | G31: =IF(F31<1,"0",IF(F31=0,"0",IF(F31=1,"1"))) -> 1
E32: ='Input Nilai'!E43 -> 31 | F32: ='Input Nilai'!F43 -> 1 | G32: =IF(F32<1,"0",IF(F32=0,"0",IF(F32=1,"1"))) -> 1
E33: ='Input Nilai'!E44 -> 32 | F33: ='Input Nilai'!F44 -> 1 | G33: =IF(F33<1,"0",IF(F33=0,"0",IF(F33=1,"1"))) -> 1
C34: ='Input Nilai'!C45 -> 9 | D34: ='Input Nilai'!D45 -> Peraturan/Kegiatan Perlindungan dan Pengelolaan Lingkungan Hidup | E34: ='Input Nilai'!E45 -> 33 | F34: ='Input Nilai'!F45 -> 1 | G34: =IF(F34=1,"2",IF(F34=0,"1")) -> 2 | H34: =((G34+G35+G36+G37)*5/5) -> 5 | I34: 4 | J34: 2 | K34: 2 | L34: 3 | M34: 3 | N34: 4 | O34: 3 | P34: 4 | Q34: 3 | R34: 3 | S34: 4 | T34: 3 | U34: 2 | V34: 4 | W34: 4 | X34: 4 | Y34: 3 | AA34: =SUM(I34:Y36)/17 -> 3.2352941 | AB34: =1/14 -> 0.071428571 | AC34: =IF(H34<1,"0",H34) -> 5 | AD34: =IF(AC34="",0,AC34) -> 5 | AE34: =AB34/5 -> 0.014285714 | AF34: =AD34*AE34 -> 0.071428571 | AJ34: =IF(AF34=0,"-", IF(H34=1,'Rekomendasi Aksi'!E34, IF(H34=2,'Rekomendasi Aksi'!E34, IF(H34=3,'Rekomendasi Aksi'!E35, IF(H34=4,'Rekomendasi Aksi'!E36, IF(H34=5,'Rekomendasi Aksi'!E37)))))) -> Melakukan kerjasama dengan dinas/lembaga/organisasi untuk indentifikasi kebutuhan, perencanaan dan pelaksanaan pengembangan/peningkatan penyelenggaraan layanan perlindungan dan pengelolaan lingkungan hidup di Desa/Kelurahan.
E35: ='Input Nilai'!E46 -> 34 | F35: ='Input Nilai'!F46 -> 1 | G35: =IF(F35<1,"0",IF(F35=0,"0",IF(F35=1,"1"))) -> 1
E36: ='Input Nilai'!E47 -> 35 | F36: ='Input Nilai'!F47 -> 1 | G36: =IF(F36<1,"0",IF(F36=0,"0",IF(F36=1,"1"))) -> 1
E37: ='Input Nilai'!E48 -> 36 | F37: ='Input Nilai'!F48 -> 1 | G37: =IF(F37<1,"0",IF(F37=0,"0",IF(F37=1,"1"))) -> 1
C38: ='Input Nilai'!C49 -> 10 | D38: ='Input Nilai'!D49 -> Peraturan dan Kegiatan Keagamaan | E38: ='Input Nilai'!E49 -> 37 | F38: ='Input Nilai'!F49 -> 0 | G38: =IF(F38=1,"2",IF(F38=0,"1")) -> 1 | H38: =((G38+G39+G40+G41)*5/5) -> 1 | I38: 3 | J38: 2 | K38: 2 | L38: 1 | M38: 2 | N38: 2 | O38: 3 | P38: 4 | Q38: 2 | R38: 2 | S38: 3 | T38: 3 | U38: 2 | V38: 1 | W38: 3 | X38: 3 | Y38: 3 | AA38: =SUM(I38:Y40)/17 -> 2.4117647 | AB38: =1/14 -> 0.071428571 | AC38: =IF(H38<1,"0",H38) -> 1 | AD38: =IF(AC38="",0,AC38) -> 1 | AE38: =AB38/5 -> 0.014285714 | AF38: =AD38*AE38 -> 0.014285714 | AJ38: =IF(AF38=0,"-", IF(H38=1,'Rekomendasi Aksi'!E38, IF(H38=2,'Rekomendasi Aksi'!E38, IF(H38=3,'Rekomendasi Aksi'!E39, IF(H38=4,'Rekomendasi Aksi'!E40, IF(H38=5,'Rekomendasi Aksi'!E41)))))) -> Pengusulan penyelenggaraan layanan keagamaan melalui mekanisme Musrenbang Desa/Kelurahan hingga Musrenbang Kabupaten/Kota, sesuai SPM bidang keagamaan.
E39: ='Input Nilai'!E50 -> 38 | F39: ='Input Nilai'!F50 -> 0 | G39: =IF(F39<1,"0",IF(F39=0,"0",IF(F39=1,"1"))) -> 0
E40: ='Input Nilai'!E51 -> 39 | F40: ='Input Nilai'!F51 -> 0 | G40: =IF(F40<1,"0",IF(F40=0,"0",IF(F40=1,"1"))) -> 0
...

Sheet Graphic
B1: =L16 -> PENILAIAN KETANGGUHAN BENCANA CUACA EKSTREM (ANGIN KENCANG)
B2: =M16 -> DESA DESA MEDARI, NGADIREJO, TEMANGGUNG, JAWA TENGAH
B3: =N16 -> TAHUN 2026
B6: NO | C6: KOMPONEN | D6: INDEKS KOMPONEN | E6: INDEKS KETANGGUHAN | F6: TINGKAT KETANGGUHAN | H6: Tingkat ketangguhan sebuah desa/kelurahan dalam menghadapi bencana dibagi kedalam tiga kriteria, yaitu:
B7: 1 | C7: Layanan Dasar | D7: =Analisa!AG2 -> 0.87142857 | E7: =Analisa!AI2 -> 57.161905 | F7: =IF(E7<=58.33,"TANGGUH PRATAMA",IF(E7>83.33,"TANGGUH UTAMA","TANGGUH MADYA")) -> TANGGUH PRATAMA | H7: Desa/Kelurahan Tangguh Bencana Utama | M7: > 83,33
B8: 2 | C8: Peraturan dan Kebijakan PB | D8: =Analisa!AG58 -> 0.52 | H8: Desa/Kelurahan Tangguh Bencana Madya | M8: 58,33 - 83,33
B9: 3 | C9: Pencegahan dan Mitigasi | D9: =Analisa!AG78 -> 0.46666667 | H9: Desa/Kelurahan Tangguh Bencana Pratama | M9: < 58,33
B10: 4 | C10: Kesiapsiagaan Darurat | D10: =Analisa!AG90 -> 0.6
B11: 5 | C11: Kesiapsiagaan Pemulihan | D11: =Analisa!AG114 -> 0.4
L16: =UPPER(CONCATENATE(L17," ",L18)) -> PENILAIAN KETANGGUHAN BENCANA CUACA EKSTREM (ANGIN KENCANG) | M16: =UPPER(CONCATENATE(M17,", ",M18,", ", M19,", ", M20)) -> DESA DESA MEDARI, NGADIREJO, TEMANGGUNG, JAWA TENGAH | N16: =UPPER(CONCATENATE(N17," ",N18)) -> TAHUN 2026 | P16: INDEKS PER KOMPONEN
L17: PENILAIAN KETANGGUHAN BENCANA | M17: =IF(ISNUMBER(SEARCH("Kelurahan",'Input Nilai'!D6)),'Input Nilai'!D6,"DESA "&'Input Nilai'!D6) -> DESA Desa Medari | N17: TAHUN | P17: =IF(ISNUMBER(SEARCH("Kelurahan",'Input Nilai'!D6)),'Input Nilai'!D6,"DESA "&'Input Nilai'!D6) -> DESA Desa Medari
L18: ='Input Nilai'!D10 -> Cuaca Ekstrem (Angin Kencang) | M18: ='Input Nilai'!D7 -> Ngadirejo | N18: =YEAR('Input Nilai'!D5) -> 2026
M19: ='Input Nilai'!D8 -> Temanggung | P19: =UPPER(CONCATENATE(P16, P17,T1)) -> INDEKS PER KOMPONEN DESA DESA MEDARI
M20: ='Input Nilai'!D9 -> Jawa Tengah

Sheet Rekomendasi
A1: REKOMENDASI KERANGKA AKSI PENINGKATAN KETANGGUHAN BENCANA
A2: =Graphic!M16 -> DESA DESA MEDARI, NGADIREJO, TEMANGGUNG, JAWA TENGAH
A4: KERANGKA AKSI
A5: A | B5: ='Input Nilai'!B13 -> LAYANAN DASAR
B6: 1 | C6: =Analisa!AJ2 -> Melakukan kerjasama dengan dinas/lembaga/organisasi untuk indentifikasi kebutuhan, perencanaan dan pelaksanaan pengembangan/peningkatan penyelenggaraan layanan pendidikan formal/non formal di Desa/Kelurahan.
B7: 2 | C7: =Analisa!AJ6 -> Melakukan kerjasama dengan dinas/lembaga/organisasi untuk indentifikasi kebutuhan, perencanaan dan pelaksanaan pengembangan/peningkatan penyelenggaraan layanan kesehatan formal/non formal di Desa/Kelurahan.
B8: 3 | C8: =Analisa!AJ10 -> Melakukan evaluasi, perencanaan dan pelaksanaan layanan sarana/prasarana transportasi
B9: 4 | C9: =Analisa!AJ14 -> Mengusulkan kerjasama dengan dinas/lembaga/organisasi untuk identifikasi kebutuhan, perencanaan dan pelaksanaan penyelenggaraan program layanan air bersih
B10: 5 | C10: =Analisa!AJ18 -> Melakukan kerjasama dengan berbagai pihak baik OPD terkait, akademisi, praktisi pangan dan gizi serta lembaga lainnya..
B11: 6 | C11: =Analisa!AJ22 -> Melakukan kerjasama dengan berbagai pihak baik OPD terkait, Akademisi, dunia usaha maupun Asosiasi layanan pengembangan ekonomi dan bisnis lainnya.
B12: 7 | C12: =Analisa!AJ26 -> Melakukan kerjasama dengan dinas/lembaga/organisasi untuk indentifikasi kebutuhan, perencanaan dan pelaksanaan pengembangan/peningkatan penyelenggaraan sarana dan prasarana komunikasi/informasi di Desa/Kelurahan.
B13: 8 | C13: =Analisa!AJ30 -> Melakukan kerjasama dengan dinas/lembaga/organisasi untuk indentifikasi kebutuhan, perencanaan dan pelaksanaan pengembangan/peningkatan penyelenggaraan pelayanan administrasi dan kependudukan di Desa/Kelurahan.
B14: 9 | C14: =Analisa!AJ34 -> Melakukan kerjasama dengan dinas/lembaga/organisasi untuk indentifikasi kebutuhan, perencanaan dan pelaksanaan pengembangan/peningkatan penyelenggaraan layanan perlindungan dan pengelolaan lingkungan hidup di Desa/Kelurahan.
B15: 10 | C15: =Analisa!AJ38 -> Pengusulan penyelenggaraan layanan keagamaan melalui mekanisme Musrenbang Desa/Kelurahan hingga Musrenbang Kabupaten/Kota, sesuai SPM bidang keagamaan.
B16: 11 | C16: =Analisa!AJ42 -> Melakukan kerjasama dengan Dinas/lembaga/organisasi untuk mengembangkan dan meningkatkan kegiatan kebudayaan
B17: 12 | C17: =Analisa!AJ46 -> Melakukan kerjasama dengan Dinas/lembaga/organisasi untuk mengembangkan dan meningkatkan kegiatan perlindungan keamanan
B18: 13 | C18: =Analisa!AJ50 -> Melakukan kerjasama dengan dinas/lembaga/organisasi untuk indentifikasi kebutuhan, perencanaan dan pelaksanaan pengembangan/peningkatan pemberdayaan perempuan dan perlindungan anak
B19: 14 | C19: =Analisa!AJ54 -> Mengusulkan pembentukan lembaga, penyelenggaraan kegiatan dan penyusunan peraturan untuk layanan khusus difabel
A20: B | B20: ='Input Nilai'!B69 -> PERATURAN DAN KEBIJAKAN PENANGGULANGAN BENCANA
B21: 15 | C21: =Analisa!AJ58 -> Mengusulkan pengkajian risiko bencana melalui mekanisme Musrenbang Desa/Kelurahan.
B22: 16 | C22: =Analisa!AJ62 -> Melakukan kerjasama dengan pihak lain untuk penyusunan dokumen RPB.
B23: 17 | C23: =Analisa!AJ66 -> Menjalin kerjasama penyelenggaraan pelatihan penanggulangan bencana dengan pihak-pihak lain.
B24: 18 | C24: =Analisa!AJ70 -> Mengusulkan pembentukan organisasi/kelompok Penanggulangan Bencana Desa melalui Musrenbang
A25: C | B25: ='Input Nilai'!B89 -> PENCEGAHAN DAN MITIGASI
B26: 19 | C26: =Analisa!AJ74 -> Mengusulkan ada Standart Operasional Prosedure atau sejenisnya mengenai kerjasama dengan pihak luar dalam pelaksanaan kegiatan penanggulangan bencana
B27: 20 | C27: =Analisa!AJ78 -> Melakukan kerjasama dengan pihak lain dalam melakukan kegiatan pencegahan bencana.
B28: 21 | C28: =Analisa!AJ82 -> Mengusulkan kegiatan mitigasi bencana menggunakan anggaran desa.
B29: 22 | C29: =Analisa!AJ86 -> Mengusulkan kegiatan sosialisasi pengetahuan kebencanaan menggunakan anggaran desa.
A30: D | B30: ='Input Nilai'!B101 -> KESIAPSIAGAAN DARURAT
B31: 23 | C31: =Analisa!AJ90 -> Desa/Kelurahan segera mengembangkan penyediaan peringatan bahaya efektif
B32: 24 | C32: =Analisa!AJ94 -> Bekerjasama dengan desa/kelurahan lain atau pihak lain dalam meningkatkan efektifitas penyebarluasan peringatah bahaya
B33: 25 | C33: =Analisa!AJ98 -> Membangun kerjasama dengan desa/kelurahan atau pihak lain tentang penyusunan atau pengembangan rencana evakuasi bencana
B34: 26 | C34: =Analisa!AJ102 -> Melakukan kerjasama dengan Dinas/lembaga/organisasi untuk mengembangkan dan meningkatkan jalur evakuasi
B35: 27 | C35: =Analisa!AJ106 -> Desa/Kelurahan perlu merencanakan dan menetapkan tempat pengungsian bencana dengan melibatkan masyarakat berpotensi terdampak bencana serta berkoordinasi dengan BPBD/dinas/lembaga/organisasi dalam sistem kesiapsiagaan setempat
B36: 28 | C36: =Analisa!AJ110 -> Desa/Kelurahan perlu melakukan uji kesiapsiagaan/simulasi menghadapi bencana secara rutin untuk meningkatkan kesiapan masyarakat dan seluruh sistem kesiapsiagaan
A37: E | B37: ='Input Nilai'!B125 -> KESIAPSIAGAAN PEMULIHAN
B38: 29 | C38: =Analisa!AJ114 -> Mengusulkan kegiatan penyusunan mekanisme penilaian pasca bencana secara mandiri menggunakan anggaran desa.
B39: 30 | C39: =Analisa!AJ118 -> Mengusulkan kegiatan penyusunan mekanisme pemulihan dini mandiri menggunakan anggaran desa.
B40: 31 | C40: =Analisa!AJ122 -> Mengusulkan kegiatan penyusunan mekanisme pengelolaan bantuan secara mandiri yang transparan dan akuntabel menggunakan anggaran desa.
B41: 32 | C41: =Analisa!AJ126 -> Melakukan kerjasama dengan pihak lain dalam melakukan pengembangan/peningkatan rencana untuk membangun fasilitas tersebut secara lebih kuat dan aman pasca bencana.

Sheet Rekomendasi Aksi
A1: Komponen | B1: Indikator | D1: Pertanyaan | E1: Rekomendasi Aksi
A2: ='Input Nilai'!B13 -> LAYANAN DASAR | B2: Indikator 1. Penyelenggaraan Layanan Pendidikan | C2: Mas Mino | D2: 1. Apakah di Desa/Kelurahan terselenggara layanan pendidikan formal atau non formal? | E2: Mengusulkan penyelenggaraan layanan pendidikan melalui mekanisme Musrenbang Desa/Kelurahan hingga Musrenbang Kabupaten/Kota, sesuai SPM bidang pendidikan.
D3: 2. Apakah penyelenggaraan layanan pendidikan tersebut sesuai harapan/kebutuhan? | E3: Melakukan evaluasi, perencanaan dan pelaksanaan perbaikan penyelenggaraan layanan pendidikan.
D4: 3. Apakah pemerintah Desa/Kelurahan mengalokasikan anggaran untuk keberlanjutan penyelenggaraan layanan pendidikan tersebut? | E4: Mengusulkan alokasi anggaran melalui mekanisme Musrenbang atau dalam musyawarah penyusunan RKPDes/Kel.
D5: 4. Apakah pemerintah Desa/Kelurahan bekerjasama dengan pihak lan dalam pengembangan/peningkatan penyelenggaraan layanan pendidikan tersebut? | E5: Melakukan kerjasama dengan dinas/lembaga/organisasi untuk indentifikasi kebutuhan, perencanaan dan pelaksanaan pengembangan/peningkatan penyelenggaraan layanan pendidikan formal/non formal di Desa/Kelurahan.
B6: Indikator 2. Penyelenggaraan Layanan Kesehatan | C6: Mas Mino | D6: 5. Apakah di Desa/Kelurahan terselenggara layanan kesehatan? | E6: Pengusulan penyelenggaraan layanan kesehatan melalui mekanisme Musrenbang Desa/Kelurahan hingga Musrenbang Kabupaten/Kota, sesuai SPM bidang pendidikan
D7: 6. Apakah penyelenggaraan layanan kesehatan tersebut bermanfaat/bisa diandalkan ? | E7: Melakuan evaluasi, perencanaan dan pelaksanaan perbaikan penyelenggaraan layanan kesehatan
D8: 7. Apakah pemerintah Desa/Kelurahan mengalokasikan anggaran untuk keberlanjutan penyelenggaraan layanan kesehatan tersebut? | E8: Mengusulkan alokasi anggaran mekanisme Musrenbang atau dalam musyawarah penyusunan RPJMDes/RKPDes/Kel
D9: 8. Apakah pemerintah Desa/Kelurahan bekerjasama dengan pihak lain untuk pengembangan/peningkatan penyelenggaraan layanan kesehatan tersebut? | E9: Melakukan kerjasama dengan dinas/lembaga/organisasi untuk indentifikasi kebutuhan, perencanaan dan pelaksanaan pengembangan/peningkatan penyelenggaraan layanan kesehatan formal/non formal di Desa/Kelurahan.
B10: Indikator 3. Sarana dan Prasarana Transportasi | C10: Pudji | D10: 9. Apakah di Desa/Kelurahan tersedia sarana/prasarana transportasi? | E10: Mengusulkan program penyediaan sarana/prasarana transportasi
D11: 10. Apakah sarana/prasarana transportasi tersebut dapat diandalkan? | E11: Melakukan evaluasi, perencanaan dan pelaksanaan layanan sarana/prasarana transportasi
D12: 11. Apakah pemerintah Desa/Kelurahan mengalokasikan anggaran untuk keberlanjutan sarana/prasarana transportasi tersebut? | E12: Mengusulkan alokasi anggaran melalui mekanisme Musrenbang Desa/Kelurahan
D13: 12. Apakah pemerintah Desa/Kelurahan bekerjasama dengan pihak lain untuk pengembangan/peningkatan sarana/prasarana transportasi tersebut? | E13: Mengusulkan kerjasama dengan dinas/lembaga/organisasi untuk identifikasi kebutuhan, perencanaan dan pelaksanaan penyelenggaraan program peningkatan sarana/prasarana transportasi
B14: Indikator 4. Penyediaan Air Bersih | C14: Pudji | D14: 13. Apakah di Desa/Kelurahan menyediakan air bersih? | E14: Mengusulkan program penyediaan air bersih melalui mekanisme Musrenbang Desa/Kelurahan
D15: 14. Apakah jumlah dan kualitas penyediaan air bersih tersebut dapat memenuhi kebutuhan? | E15: Melakukan evaluasi, perencanaan dan pelaksanaan program layanan air bersih
D16: 15. Apakah pemerintah Desa/Kelurahan mengalokasikan anggaran untuk keberlanjutan penyediaan air bersih tersebut? | E16: Mengusulkan alokasi anggaran melalui mekanisme Musrenbang Desa/Kelurahan
D17: 16. Apakah pemerintah Desa/Kelurahan bekerjasama dengan pihak lain pengembangan/peningkatan penyediaan air bersih tersebut? | E17: Mengusulkan kerjasama dengan dinas/lembaga/organisasi untuk identifikasi kebutuhan, perencanaan dan pelaksanaan penyelenggaraan program layanan air bersih
B18: Indikator 5. Program dan Kegiatan Pangan & Gizi | C18: Mbak Heni | D18: 17 Apakah pemerintah Desa/Kelurahan menyelenggarakan program/kegiatan pangan dan gizi? | E18: Mengusulkan program/kegiatan pangan dan gizi memalui mekanisme Musrenbang Desa/Kelurahan
D19: 18 Apakah program/kegiatan pangan & gizi tersebut dapat memenuhi kebutuhan? | E19: Melakukan evaluasi dan monitoring dalam perencanaan dan pelaksanaan program/kegiatan pangan dan gizi
D20: 19 Apakah pemerintah Desa/Kelurahan mengalokasikan anggaran untuk keberlanjutan program/kegiatan pangan dan gizi tersebut? | E20: Mengusulkan anggaran program/kegiatan pangan dan gizi melalui mekanisme Musrenbang Desa/kelurahan
D21: 20 Apakah pemerintah Desa/Kelurahan bekerjasama dengan pihak lain untuk pengembangan/peningkatan program/kegiatan pangan dan gizi tersebut? | E21: Melakukan kerjasama dengan berbagai pihak baik OPD terkait, akademisi, praktisi pangan dan gizi serta lembaga lainnya..
B22: Indikator 6. Pemberdayaan UMKM dan Peningkatan Ekonomi Melalui BUMDES | C22: Mbak Heni | D22: 21 Apakah pemerintah Desa/Kelurahan menyelenggarakan program pemberdayaan UMKM dan/atau pengembangan ekonomi melalui BUMDES? | E22: Mengusulkan program pemberdayaan UMKM dan/atau pengembangan ekonomi melalui BUMDES dalam Musrenbang Des/Kelurahan.
D23: 22 Apakah program pemberdayaan UMKM dan/atau pengembangan ekonomi melalui BUMDES bermanfaat? | E23: Melakukan pelatihan dan pendampingan bagi UMKM dan/atau pengembangan ekonomi melalui BUMDES
D24: 23. Apakah pemerintah Desa/Kelurahan mengalokasikan anggaran untuk keberlanjutan program pemberdayaan UMKM dan/atau pengembangan ekonomi melalui BUMDES? | E24: Megusulkan aggaran program pemberdayaan UMKM dan/atau pengembangan ekonomi melalui RKP Desamaupun RKP Kelurahan
D25: 24 Apakah pemerintah Desa/Kelurahan bekerjasama dengan pihak lain untuk pengembangan dan peningkatan program pemberdayaan UMKM dan/atau pengembangan ekonomi melalui BUMDES? | E25: Melakukan kerjasama dengan berbagai pihak baik OPD terkait, Akademisi, dunia usaha maupun Asosiasi layanan pengembangan ekonomi dan bisnis lainnya.
B26: Indikator 7. Sarana dan Prasarana Komunikasi/Informasi | C26: Ronggo | D26: 25. Apakah di Desa/Kelurahan terdapat/tersedia sarana dan prasarana komunikasi/informasi? | E26: Mengusulkan penyediaan sarana dan prasarana komunikasi/informasi dalam musrenbangdes maupun musrenbangkel sesuai SPM sarana dan prasarana komunikasi/informasi
D27: 26. Apakah sarana dan prasarana komunikasi/informasi tersebut dapat diandalkan? | E27: Melakukan monitoring, evaluasi dan perencanaan terhadap optimalnya sarana dan prasarana komunikasi/informasi
D28: 27. Apakah pemerintah Desa/Kelurahan mengalokasikan anggaran untuk keberlanjutan sarana dan prasarana komunikasi/informasi tersebut? | E28: Mengusulkan anggaran untuk penyediaan sarana dan prasarana komunikasi/informasi dalam RKPDes maupun RKP Kelurahan
D29: 28. Apakah pemerintah Desa/Kelurahan bekerjasama dengan pihak lain dalam pengembangan/peningkatan sarana dan prasarana komunikasi/informasi tersebut? | E29: Melakukan kerjasama dengan dinas/lembaga/organisasi untuk indentifikasi kebutuhan, perencanaan dan pelaksanaan pengembangan/peningkatan penyelenggaraan sarana dan prasarana komunikasi/informasi di Desa/Kelurahan.
B30: Indikator 8. Pelayanan Administrasi dan Kependudukan | C30: Ronggo | D30: 29. Apakah pemerintah Desa/Kelurahan menyelenggarakan pelayanan administrasi dan kependudukan? | E30: Mengusulkan penyelenggaraan pelayanan administrasi dan kependudukan dalam musrenbangdes maupun musrenbangkel sesuai dengan SPM pelayanan adminstrasi dan kependudukan
D31: 30. Apakah penyelenggaraan pelayanan administrasi dan kependudukan tersebut dapat diandalkan (cepat dan mudah)? | E31: Melakukan monitoring, evaluasi, perencanaan dan pelaksanaan terhadap pelayanan administrasi dan kependudukan
D32: 31. Apakah pemerintah Desa/Kelurahan mengalokasikan anggaran untuk keberlanjutan menyelenggarakan pelayanan administrasi dan kependudukan tersebut? | E32: Mengusulkan anggaran untuk keberlanjutan penyelenggaraan pelayanan administrasi dan kependudukan dalam RKPDes maupun RKP Kelurahan
D33: 32. Apakah pemerintah Desa/Kelurahan bekerjasama dengan pihak lain dalam pengembangan/peningkatan menyelenggarakan pelayanan administrasi dan kependudukan tersebut? | E33: Melakukan kerjasama dengan dinas/lembaga/organisasi untuk indentifikasi kebutuhan, perencanaan dan pelaksanaan pengembangan/peningkatan penyelenggaraan pelayanan administrasi dan kependudukan di Desa/Kelurahan.
B34: Indikator 9. Peraturan/Kegiatan Perlindungan dan Pengelolaan Lingkungan Hidup | C34: Gandar | D34: 33. Apakah pemerintah Desa/Kelurahan memiliki peraturan atau kegiatan perlindungan dan pengelolaan lingkungan hidup? | E34: Pengusulan penyelenggaraan layanan perlindungan dan pengelolaan lingkungan hidup melalui mekanisme Musrenbang Desa/Kelurahan hingga Musrenbang Kabupaten/Kota, sesuai SPM bidang lingkungan hidup.
D35: 34. Apakah peraturan atau kegiatan perlindungan dan pengelolaan lingkungan hidup tersebut bermanfaat? | E35: Melakuan evaluasi, perencanaan dan pelaksanaan perbaikan penyelenggaraan layanan perlindungan dan pengelolaan lingkungan hidup.
D36: 35. Apakah pemerintah Desa/Kelurahan mengalokasikan anggaran untuk keberlanjutan perlindungan dan pengelolaan lingkungan hidup tersebut? | E36: Pengusulan alokasi anggaran mekanisme Musrenbang atau dalam musyawarah penyusunan RKPDes/Kel.
D37: 36. Apakah pemerintah Desa/Kelurahan bekerjasama dengan pihak lain dalam pengembangan/peningkatan perlindungan dan pengelolaan lingkungan hidup tersebut? | E37: Melakukan kerjasama dengan dinas/lembaga/organisasi untuk indentifikasi kebutuhan, perencanaan dan pelaksanaan pengembangan/peningkatan penyelenggaraan layanan perlindungan dan pengelolaan lingkungan hidup di Desa/Kelurahan.
B38: Indikator 10. Peraturan dan Kegiatan Keagamaan | C38: Gandar | D38: 37. Apakah pemerintah di Desa/Kelurahan memiliki peraturan atau kegiatan keagamaan? | E38: Pengusulan penyelenggaraan layanan keagamaan melalui mekanisme Musrenbang Desa/Kelurahan hingga Musrenbang Kabupaten/Kota, sesuai SPM bidang keagamaan.
D39: 38. Apakah peraturan dan kegiatan keagamaan tersebut bermanfaat? | E39: Melakukan evaluasi, perencanaan dan pelaksanaan perbaikan penyelenggaraan layanan keagamaan.
D40: 39. Apakah pemerintah Desa/Kelurahan mengalokasikan anggaran untuk penerapan aturan atau keberlanjutan peraturan dan kegiatan keagamaan tersebut? | E40: Pengusulan alokasi anggaran mekanisme Musrenbang atau dalam musyawarah penyusunan RKPDes/Kel
...
